<mujocoinclude>
    <body name="base_link">
        <inertial pos="0.00137614 -0.0126343 0.0980263" quat="0.535082 0.473426 -0.464716 0.523062" mass="15.615" diaginertia="0.665833 0.618181 0.259713"/>
        <geom type="mesh" rgba="1 1 1 1" mesh="e3_desktop_base_link" contype="0" conaffinity="0" />
        <geom pos="0.0185 0.3 0.14502" quat="1 0 0 0" type="mesh" rgba="1 1 1 1" mesh="arm_base_link"/>
        <geom pos="0.0185 -0.3 0.14502" quat="1 0 0 0" type="mesh" rgba="1 1 1 1" mesh="arm_base_link"/>
        <geom pos="0.074 0 0.53575" quat="0.9238795 0.0 0.3826834 0.0" type="mesh" mesh="camera_link" rgba="0.1 0.1 0.1 1" contype="0" conaffinity="0" />
        <camera name="head_camera" pos="0.084 0 0.52075" quat="0.6532815 0.2705981 -0.2705981 -0.6532815" fovy="70"/>

        # left link 1
        <body name="left_link_1" pos="0.0185 0.3 0.21152">
            <inertial pos="0.008 -0.0023 0.0213" quat="0.707107 0.707107 0 0" mass="0.2154" diaginertia="0.0003 0.0003 0.0002"/>
            <joint name="left_joint_1" pos="0 0 0" axis="0 0 1" range="-2.7 2.7" limited="true" armature="0.1" damping="3.0" frictionloss="1.0"/>
            <geom type="mesh" rgba="0.92549 0.92549 0.92549 1" mesh="arm_link_1"/>

            # left link 2
            <body name="left_link_2" pos="0.02 0 0.045">
                <inertial pos="0.0001 -0.0028 0.1317" quat="0.999789 0.0205404 0 0" mass="1.3123" diaginertia="0.018 0.0177288 0.000671225"/>
                <joint name="left_joint_2" pos="0 0 0" axis="0 1 0" range="-1.57 2.09" limited="true" armature="0.1" damping="3.0" frictionloss="1.0"/>
                <geom type="mesh" rgba="1 1 1 1" mesh="arm_link_2"/>

                # left link 3
                <body name="left_link_3" pos="0 0 0.264">
                    <inertial pos="-0.051 0.0008 0.1447" quat="0.996909 0.0323182 -0.0688403 -0.019747" mass="1.1083" diaginertia="0.0115968 0.0112369 0.00136632"/>
                    <joint name="left_joint_3" pos="0 0 0" axis="0 1 0" range="0 3.14" limited="true" armature="0.1" damping="3.0" frictionloss="1.0"/>
                    <geom type="mesh" rgba="1 1 1 1" mesh="arm_link_3"/>

                    # left link 4
                    <body name="left_link_4" pos="-0.06 0 0.245">
                        <inertial pos="-0.0597 -0.001 0.0572" quat="0 0.92388 0 0.382683" mass="0.5398" diaginertia="0.0011 0.001 0.0005"/>
                        <joint name="left_joint_4" pos="0 0 0" axis="0 1 0" range="-1.57 1.57" limited="true" armature="0.1" damping="3.0" frictionloss="1.0"/>
                        <geom type="mesh" rgba="0.792157 0.792157 0.792157 1" mesh="arm_link_4"/>

                        # left link 5
                        <body name="left_link_5" pos="-0.0553006 0 0.07025">
                            <inertial pos="0.0292 0.0001 -0.0107" quat="0.707107 0 0 0.707107" mass="0.3984" diaginertia="0.0003 0.0002 0.0002"/>
                            <joint name="left_joint_5" pos="0 0 0" axis="-1 0 0" range="-1.57 1.57" limited="true" armature="0.1" damping="3.0" frictionloss="1.0"/>
                            <geom type="mesh" rgba="0.898039 0.917647 0.929412 1" mesh="arm_link_5"/>

                            # left gripper base link
                            <body name="left_gripper_base_link" pos="0.0578 0 0.02895" quat="0.707107 0.0 -0.707107 0.0">
                                <inertial pos="-0.0139 0.0001 0.0578" quat="0.567843 0.421372 0.421372 0.567843" mass="0.7651" diaginertia="0.0021 0.00143028 0.00106972"/>
                                <joint name="left_joint_6" pos="0 0 0" axis="1 0 0" range="-1.57 1.57" limited="true" armature="0.1" damping="3.0" frictionloss="1.0"/>
                                <geom type="mesh" rgba="1 1 1 1" mesh="gripper_base_link"/>
                                <geom pos="0.04 0 0.12" quat="0.6830127 0.6830127 0.1830127 -0.1830127" type="mesh" rgba="0.1 0.1 0.1 1" mesh="camera_link" />
                                <camera name="left_camera" pos="0.066 0 0.105" quat="0.8660254 0.0 -0.5 0.0" fovy="50"/>

                                # ee frame
                                <body name="left_ee_frame" pos="0.1870 0.0 0.0" quat="1 0 0 0">
                                    <geom type="cylinder" size="0.002 0.01" pos="0.01 0.00 0.00" quat="0.7071068 0.0000000 0.7071068 0.0000000" rgba="1 0 0 1" contype="0" conaffinity="0" group="4"/>
                                    <geom type="cylinder" size="0.002 0.01" pos="0.00 0.01 0.00" quat="0.7071068 0.7071068 0.0000000 0.0000000" rgba="0 1 0 1" contype="0" conaffinity="0" group="4"/>
                                    <geom type="cylinder" size="0.002 0.01" pos="0.00 0.00 0.01" quat="1.0000000 0.0000000 0.0000000 0.0000000" rgba="0 0 1 1" contype="0" conaffinity="0" group="4"/>
                                </body>

                                # gripper helper
                                <body name="left_gripper_left_helper_link" pos="0.057667 0.030604 2.5e-05">
                                    <inertial pos="0.00299357 0.0232625 -5e-05" quat="0.996724 0 0 0.0808839" mass="0.00594562" diaginertia="2.74798e-06 1.47567e-06 1.34732e-06"/>
                                    <joint name="left_gripper_left_help_joint" pos="0 0 0" axis="0 0 -1" range="0 1.52" limited="true" armature="0.01" damping="1.0" frictionloss="0.1" />
                                    <geom type="mesh" rgba="1 1 1 1" mesh="gripper_left_helper_link"/>
                                </body>
                                <body name="left_gripper_right_helper_link" pos="0.057667 -0.030604 2.5e-05">
                                    <inertial pos="0.00299357 -0.0232625 -5e-05" quat="0.996724 0 0 -0.0808839" mass="0.00594562" diaginertia="2.74798e-06 1.47567e-06 1.34732e-06"/>
                                    <joint name="left_gripper_right_help_joint" pos="0 0 0" axis="0 0 1" range="0 1.52" limited="true" armature="0.01" damping="1.0" frictionloss="0.1" />
                                    <geom type="mesh" rgba="1 1 1 1" mesh="gripper_right_helper_link"/>
                                </body>

                                # left gripper
                                <body name="left_gripper_left_link_1" pos="0.0721 0.014 2.5e-05">
                                    <inertial pos="0.00299357 0.0232625 -5e-05" quat="0.996724 0 0 0.0808839" mass="0.00594562" diaginertia="2.74798e-06 1.47567e-06 1.34732e-06"/>
                                    <joint name="left_gripper_left_joint_1" pos="0 0 0" axis="0 0 -1" range="0 1.52" limited="true" armature="0.01" damping="1.0" frictionloss="0.1" />
                                    <geom type="mesh" rgba="1 1 1 1" mesh="gripper_left_link_1"/>

                                    <body name="left_gripper_left_link_2" pos="0.0085108 0.04927 0">
                                        <inertial pos="0.0255016 0.00914642 -0.00175617" quat="0.424541 0.412629 0.571518 0.568216" mass="0.0339319" diaginertia="1.36949e-05 1.35554e-05 3.4264e-06"/>
                                        <joint name="left_gripper_left_joint_2" pos="0 0 0" axis="0 0 1" range="0 1.52" limited="true" armature="0.01" damping="1.0" frictionloss="0.1" />
                                        <geom type="mesh" rgba="1 1 1 1" mesh="gripper_left_link_2"/>
                                    </body>
                                </body>

                                # right gripper
                                <body name="left_gripper_right_link_1" pos="0.0721 -0.014 2.5e-05">
                                    <inertial pos="0.00299357 -0.0232625 -5e-05" quat="0.996724 0 0 -0.0808839" mass="0.00594562" diaginertia="2.74798e-06 1.47567e-06 1.34732e-06"/>
                                    <joint name="left_gripper_right_joint_1" pos="0 0 0" axis="0 0 1" range="0 1.52" limited="true" armature="0.01" damping="1.0" frictionloss="0.1" />
                                    <geom type="mesh" rgba="1 1 1 1" mesh="gripper_right_link_1"/>

                                    <body name="left_gripper_right_link_2" pos="0.0085108 -0.04927 0">
                                        <inertial pos="0.0255016 -0.00914642 -0.00175616" quat="0.568212 0.571522 0.412623 0.424547" mass="0.0339319" diaginertia="1.36948e-05 1.35553e-05 3.4264e-06"/>
                                        <joint name="left_gripper_right_joint_2" pos="0 0 0" axis="0 0 -1" range="0 1.52" limited="true" armature="0.01" damping="1.0" frictionloss="0.1" />
                                        <geom type="mesh" rgba="1 1 1 1" mesh="gripper_right_link_2"/>
                                    </body>
                                </body>
                            </body>
                        </body>
                    </body>
                </body>
            </body>
        </body>

        # right link 1
        <body name="right_link_1" pos="0.0185 -0.3 0.21152">
            <inertial pos="0.008 -0.0023 0.0213" quat="0.707107 0.707107 0 0" mass="0.2154" diaginertia="0.0003 0.0003 0.0002"/>
            <joint name="right_joint_1" pos="0 0 0" axis="0 0 1" range="-2.7 2.7" limited="true" armature="0.1" damping="3.0" frictionloss="1.0"/>
            <geom type="mesh" rgba="0.92549 0.92549 0.92549 1" mesh="arm_link_1"/>

            # right link 2
            <body name="right_link_2" pos="0.02 0 0.045">
                <inertial pos="0.0001 -0.0028 0.1317" quat="0.999789 0.0205404 0 0" mass="1.3123" diaginertia="0.018 0.0177288 0.000671225"/>
                <joint name="right_joint_2" pos="0 0 0" axis="0 1 0" range="-1.57 2.09" limited="true" armature="0.1" damping="3.0" frictionloss="1.0"/>
                <geom type="mesh" rgba="1 1 1 1" mesh="arm_link_2"/>

                # right link 3
                <body name="right_link_3" pos="0 0 0.264">
                    <inertial pos="-0.051 0.0008 0.1447" quat="0.996909 0.0323182 -0.0688403 -0.019747" mass="1.1083" diaginertia="0.0115968 0.0112369 0.00136632"/>
                    <joint name="right_joint_3" pos="0 0 0" axis="0 1 0" range="0 3.14" limited="true" armature="0.1" damping="3.0" frictionloss="1.0"/>
                    <geom type="mesh" rgba="1 1 1 1" mesh="arm_link_3"/>

                    # right link 4
                    <body name="right_link_4" pos="-0.06 0 0.245">
                        <inertial pos="-0.0597 -0.001 0.0572" quat="0 0.92388 0 0.382683" mass="0.5398" diaginertia="0.0011 0.001 0.0005"/>
                        <joint name="right_joint_4" pos="0 0 0" axis="0 1 0" range="-1.57 1.57" limited="true" armature="0.1" damping="3.0" frictionloss="1.0"/>
                        <geom type="mesh" rgba="0.792157 0.792157 0.792157 1" mesh="arm_link_4"/>

                        # right link 5
                        <body name="right_link_5" pos="-0.0553006 0 0.07025">
                            <inertial pos="0.0292 0.0001 -0.0107" quat="0.707107 0 0 0.707107" mass="0.3984" diaginertia="0.0003 0.0002 0.0002"/>
                            <joint name="right_joint_5" pos="0 0 0" axis="-1 0 0" range="-1.57 1.57" limited="true" armature="0.1" damping="3.0" frictionloss="1.0"/>
                            <geom type="mesh" rgba="0.898039 0.917647 0.929412 1" mesh="arm_link_5"/>

                            # right gripper base link
                            <body name="right_gripper_base_link" pos="0.0578 0 0.02895" quat="0.707107 0.0 -0.707107 0.0">
                                <inertial pos="-0.0139 0.0001 0.0578" quat="0.567843 0.421372 0.421372 0.567843" mass="0.7651" diaginertia="0.0021 0.00143028 0.00106972"/>
                                <joint name="right_joint_6" pos="0 0 0" axis="1 0 0" range="-1.57 1.57" limited="true" armature="0.1" damping="3.0" frictionloss="1.0"/>
                                <geom type="mesh" rgba="1 1 1 1" mesh="gripper_base_link"/>
                                <geom pos="0.04 0 0.12" quat="0.6830127 0.6830127 0.1830127 -0.1830127" type="mesh" rgba="0.1 0.1 0.1 1" mesh="camera_link" />
                                <camera name="right_camera" pos="0.066 0 0.105" quat="0.8660254 0.0 -0.5 0.0" fovy="50"/>

                                # ee frame
                                <body name="right_ee_frame" pos="0.1870 0.0 0.0" quat="1 0 0 0">
                                    <geom type="cylinder" size="0.002 0.01" pos="0.01 0.00 0.00" quat="0.7071068 0.0000000 0.7071068 0.0000000" rgba="1 0 0 1" contype="0" conaffinity="0" group="4"/>
                                    <geom type="cylinder" size="0.002 0.01" pos="0.00 0.01 0.00" quat="0.7071068 0.7071068 0.0000000 0.0000000" rgba="0 1 0 1" contype="0" conaffinity="0" group="4"/>
                                    <geom type="cylinder" size="0.002 0.01" pos="0.00 0.00 0.01" quat="1.0000000 0.0000000 0.0000000 0.0000000" rgba="0 0 1 1" contype="0" conaffinity="0" group="4"/>
                                </body>

                                # gripper helper
                                <body name="right_gripper_left_helper_link" pos="0.057667 0.030604 2.5e-05">
                                    <inertial pos="0.00299357 0.0232625 -5e-05" quat="0.996724 0 0 0.0808839" mass="0.00594562" diaginertia="2.74798e-06 1.47567e-06 1.34732e-06"/>
                                    <joint name="right_gripper_left_help_joint" pos="0 0 0" axis="0 0 -1" range="0 1.52" limited="true" armature="0.01" damping="1.0" frictionloss="0.1" />
                                    <geom type="mesh" rgba="1 1 1 1" mesh="gripper_left_helper_link"/>
                                </body>
                                <body name="right_gripper_right_helper_link" pos="0.057667 -0.030604 2.5e-05">
                                    <inertial pos="0.00299357 -0.0232625 -5e-05" quat="0.996724 0 0 -0.0808839" mass="0.00594562" diaginertia="2.74798e-06 1.47567e-06 1.34732e-06"/>
                                    <joint name="right_gripper_right_help_joint" pos="0 0 0" axis="0 0 1" range="0 1.52" limited="true" armature="0.01" damping="1.0" frictionloss="0.1" />
                                    <geom type="mesh" rgba="1 1 1 1" mesh="gripper_right_helper_link"/>
                                </body>

                                # left gripper
                                <body name="right_gripper_left_link_1" pos="0.0721 0.014 2.5e-05">
                                    <inertial pos="0.00299357 0.0232625 -5e-05" quat="0.996724 0 0 0.0808839" mass="0.00594562" diaginertia="2.74798e-06 1.47567e-06 1.34732e-06"/>
                                    <joint name="right_gripper_left_joint_1" pos="0 0 0" axis="0 0 -1" range="0 1.52" limited="true" armature="0.01" damping="1.0" frictionloss="0.1" />
                                    <geom type="mesh" rgba="1 1 1 1" mesh="gripper_left_link_1"/>

                                    <body name="right_gripper_left_link_2" pos="0.0085108 0.04927 0">
                                        <inertial pos="0.0255016 0.00914642 -0.00175617" quat="0.424541 0.412629 0.571518 0.568216" mass="0.0339319" diaginertia="1.36949e-05 1.35554e-05 3.4264e-06"/>
                                        <joint name="right_gripper_left_joint_2" pos="0 0 0" axis="0 0 1" range="0 1.52" limited="true" armature="0.01" damping="1.0" frictionloss="0.1" />
                                        <geom type="mesh" rgba="1 1 1 1" mesh="gripper_left_link_2"/>
                                    </body>
                                </body>

                                # right gripper
                                <body name="right_gripper_right_link_1" pos="0.0721 -0.014 2.5e-05">
                                    <inertial pos="0.00299357 -0.0232625 -5e-05" quat="0.996724 0 0 -0.0808839" mass="0.00594562" diaginertia="2.74798e-06 1.47567e-06 1.34732e-06"/>
                                    <joint name="right_gripper_right_joint_1" pos="0 0 0" axis="0 0 1" range="0 1.52" limited="true" armature="0.01" damping="1.0" frictionloss="0.1" />
                                    <geom type="mesh" rgba="1 1 1 1" mesh="gripper_right_link_1"/>

                                    <body name="right_gripper_right_link_2" pos="0.0085108 -0.04927 0">
                                        <inertial pos="0.0255016 -0.00914642 -0.00175616" quat="0.568212 0.571522 0.412623 0.424547" mass="0.0339319" diaginertia="1.36948e-05 1.35553e-05 3.4264e-06"/>
                                        <joint name="right_gripper_right_joint_2" pos="0 0 0" axis="0 0 -1" range="0 1.52" limited="true" armature="0.01" damping="1.0" frictionloss="0.1" />
                                        <geom type="mesh" rgba="1 1 1 1" mesh="gripper_right_link_2"/>
                                    </body>
                                </body>
                            </body>
                        </body>
                    </body>
                </body>
            </body>
        </body>
    </body>
</mujocoinclude>
