<mujocoinclude>
    <body name="base_link">
        <inertial pos="0.00137614 -0.0126343 0.0980263" quat="0.535082 0.473426 -0.464716 0.523062" mass="15.615" diaginertia="0.665833 0.618181 0.259713"/>
        <geom type="mesh" rgba="1 1 1 1" mesh="e3_desktop_base_link" contype="0" conaffinity="0" />
        <geom pos="0.0185 0.3 0.14502" quat="1 0 0 0" type="mesh" rgba="1 1 1 1" mesh="arm_base_link"/>
        <geom pos="0.0185 -0.3 0.14502" quat="1 0 0 0" type="mesh" rgba="1 1 1 1" mesh="arm_base_link"/>
        <camera name="head_camera" pos="0.084 0 0.52075" quat="0.6532815 0.2705981 -0.2705981 -0.6532815" fovy="70"/>
        <geom pos="0.074 0 0.53575" quat="0.9238795 0.0 0.3826834 0.0" type="mesh" mesh="camera_link" rgba="0.1 0.1 0.1 1" contype="0" conaffinity="0" />

        # left link 1
        <body name="left_link_1" pos="0.0185 0.3 0.21152">
            <inertial pos="0.008 -0.0023 0.0213" quat="0.707107 0.707107 0 0" mass="0.2154" diaginertia="0.0003 0.0003 0.0002"/>
            <joint name="left_joint_1" pos="0 0 0" axis="0 0 1" range="-2.61 3.14" limited="true" armature="0.1" damping="3.0" frictionloss="1.0"/>
            <geom type="mesh" rgba="0.92549 0.92549 0.92549 1" mesh="arm_link_1"/>

            # left link 2
            <body name="left_link_2" pos="0.02 0 0.045">
                <inertial pos="0.0001 -0.0028 0.1317" quat="0.999789 0.0205404 0 0" mass="1.3123" diaginertia="0.018 0.0177288 0.000671225"/>
                <joint name="left_joint_2" pos="0 0 0" axis="0 1 0" range="-1.57 2.09" limited="true" armature="0.1" damping="3.0" frictionloss="1.0"/>
                <geom type="mesh" rgba="1 1 1 1" mesh="arm_link_2"/>

                # left link 3
                <body name="left_link_3" pos="0 0 0.264">
                    <inertial pos="-0.051 0.0008 0.1447" quat="0.996909 0.0323182 -0.0688403 -0.019747" mass="1.1083" diaginertia="0.0115968 0.0112369 0.00136632"/>
                    <joint name="left_joint_3" pos="0 0 0" axis="0 1 0" range="0 3.14" limited="true" armature="0.1" damping="3.0" frictionloss="1.0"/>
                    <geom type="mesh" rgba="1 1 1 1" mesh="arm_link_3"/>

                    # left link 4
                    <body name="left_link_4" pos="-0.06 0 0.245">
                        <inertial pos="-0.0597 -0.001 0.0572" quat="0 0.92388 0 0.382683" mass="0.5398" diaginertia="0.0011 0.001 0.0005"/>
                        <joint name="left_joint_4" pos="0 0 0" axis="0 1 0" range="-1.57 1.57" limited="true" armature="0.1" damping="3.0" frictionloss="1.0"/>
                        <geom type="mesh" rgba="0.792157 0.792157 0.792157 1" mesh="arm_link_4"/>

                        # left link 5
                        <body name="left_link_5" pos="-0.0553006 0 0.07025">
                            <inertial pos="0.0292 0.0001 -0.0107" quat="0.707107 0 0 0.707107" mass="0.3984" diaginertia="0.0003 0.0002 0.0002"/>
                            <joint name="left_joint_5" pos="0 0 0" axis="-1 0 0" range="-1.57 1.57" limited="true" armature="0.1" damping="3.0" frictionloss="1.0"/>
                            <geom type="mesh" rgba="0.898039 0.917647 0.929412 1" mesh="arm_link_5"/>

                            # left picker base link
                            <body name="left_picker_base_link" pos="0.0547 0 0.02895">
                                <inertial pos="0.00913219 -0.00104428 0.0437714" quat="0.779177 -0.153227 -0.105966 0.598478" mass="0.416893" diaginertia="0.00112999 0.000894143 0.000426247"/>
                                <joint name="left_joint_6" pos="0 0 0" axis="0 0 1" range="-1.57 1.57" limited="true" armature="0.1" damping="3.0" frictionloss="1.0"/>
                                <geom pos="0 0 0.005" type="mesh" mesh="picker_base_link" rgba="0.75 0.75 0.75 1.0" />
                                <camera name="left_camera" pos="-0.07 0.0 0.03" quat="0.1227878 0.6963642 -0.6963642 -0.1227878" fovy="50"/>
                                <geom pos="-0.08 0.0 0.015" quat="0.819152 0.0 -0.5735764 0.0" type="mesh" mesh="camera_link" rgba="0.1 0.1 0.1 1" contype="0" conaffinity="0" />

                                # left narrow gripper
                                <body name="left_picker_narrow1_link" pos="0 -0.0195 0.0565" quat="0.0 -0.707 0.0 -0.707">
                                    <inertial pos="0.0094685 0.0068806 6.5437e-05" quat="0.488058 0.00022793 0.00062709 0.872811" mass="0.025428" diaginertia="2.65562e-06 1.69368e-06 1.5501e-06"/>
                                    <joint name="left_hand_narrow1_joint" pos="0 0 0" axis="0 0 1" range="0.0 0.8" limited="true" armature="0.01" damping="1.0" frictionloss="0.1" />
                                    <geom type="mesh" mesh="picker_narrow1_link" rgba="0.75 0.75 0.75 1.0" />

                                    <body name="left_picker_narrow2_link" pos="0.030852 0.018551 0">
                                        <inertial pos="0.0088027 -0.007035 1.6424e-05" quat="0.259339 0.661207 -0.251356 0.657547" mass="0.0040132" diaginertia="1.70091e-07 1.66561e-07 5.03584e-08"/>
                                        <joint name="left_hand_narrow2_joint" pos="0 0 0" axis="0 0 -1" range="-1.57 1.57" limited="true" armature="0.001" damping="1.0" frictionloss="0.1" springref="-0.01" stiffness="1.0" />
                                        <geom type="mesh" mesh="picker_narrow2_link" rgba="0.75 0.75 0.75 1.0" />

                                        <body name="left_picker_narrow3_link" pos="0.018118 -0.01574 0">
                                            <inertial pos="0.012508 -0.0079729 9.4339e-05" quat="0.575033 0.575033 0.411506 0.411506" mass="0.018029" diaginertia="2.75843e-06 2.3252e-06 9.52273e-07"/>
                                            <joint name="left_hand_narrow3_joint" pos="0 0 0" axis="0 0 -1" range="-0.5 0.5" limited="true" armature="0.001" damping="1.0" frictionloss="0.1" />
                                            <geom type="mesh" mesh="picker_narrow3_link" rgba="0.75 0.75 0.75 1.0" />
                                        </body>
                                    </body>
                                </body>

                                # left narrow helper
                                <body name="left_picker_narrow_loop_link" pos="0 -0.021633 0.07387" quat="0.0 -0.707 0.0 -0.707">
                                    <inertial pos="0.014869 -0.0036066 0.00029307" quat="0.800794 2.10378e-06 -6.78039e-07 0.59894" mass="0.022591" diaginertia="4.76981e-06 4.35879e-06 6.0445e-07"/>
                                    <joint name="left_hand_narrow_loop_joint" pos="0 0 0" axis="0 0 -1" limited="auto" armature="0.0" damping="0.01" frictionloss="0.01" />
                                    <geom type="mesh" mesh="picker_narrow_loop_link" rgba="0.75 0.75 0.75 1.0" />
                                </body>

                                # left wide gripper
                                <body name="left_picker_wide1_link" pos="0 0.0195 0.0565" quat="0.0 -0.707 0.0 -0.707">
                                    <inertial pos="0.0095051 -0.0068479 6.8268e-05" quat="0.872477 -0.000843631 -0.000472499 0.488655" mass="0.025428" diaginertia="2.65502e-06 1.69428e-06 1.5501e-06"/>
                                    <joint name="left_hand_wide1_joint" pos="0 0 0" axis="0 0 -1" range="0.0 0.8" limited="true" armature="0.1" damping="1.0" frictionloss="0.1" />
                                    <geom type="mesh" mesh="picker_wide1_link" rgba="0.75 0.75 0.75 1.0" />

                                    <body name="left_picker_wide2_link" pos="0.030852 -0.018551 0">
                                        <inertial pos="0.0088027 0.007035 -1.6424e-05" quat="-0.251356 0.657548 0.259339 0.661207" mass="0.0040132" diaginertia="1.70091e-07 1.66561e-07 5.03584e-08"/>
                                        <joint name="left_hand_wide2_joint" pos="0 0 0" axis="0 0 -1" range="-1.57 1.57" limited="true" armature="0.001" damping="1.0" frictionloss="0.1" springref="0.01" stiffness="1.0" />
                                        <geom type="mesh" mesh="picker_wide2_link" rgba="0.75 0.75 0.75 1.0" />

                                        <body name="left_picker_wide3_link" pos="0.018118 0.01574 0">
                                            <inertial pos="0.016206 0.0094593 4.7668e-05" quat="0.574355 3.4175e-06 6.47256e-06 0.818606" mass="0.035835" diaginertia="1.16461e-05 8.09447e-06 4.6309e-06"/>
                                            <joint name="left_hand_wide3_joint" pos="0 0 0" axis="0 0 -1" range="-0.5 0.5" limited="true" armature="0.001" damping="1.0" frictionloss="0.1" />
                                            <geom type="mesh" mesh="picker_wide3_link" rgba="0.75 0.75 0.75 1.0" />
                                        </body>
                                    </body>
                                </body>

                                # left wide helper
                                <body name="left_picker_wide_loop_link" pos="0 0.021633 0.07387" quat="0.0 -0.707 0.0 -0.707">
                                    <inertial pos="0.016268 0.0040555 0.00030323" quat="0.599119 -2.137e-06 -5.96717e-07 0.80066" mass="0.025142" diaginertia="6.26903e-06 5.85397e-06 6.2389e-07"/>
                                    <joint name="left_hand_wide_loop_joint" pos="0 0 0" axis="0 0 -1" limited="auto" armature="0.0" damping="0.01" frictionloss="0.01" />
                                    <geom type="mesh" mesh="picker_wide_loop_link" rgba="0.75 0.75 0.75 1.0" />
                                </body>
                            </body>
                        </body>
                    </body>
                </body>
            </body>
        </body>

        # right link 1
        <body name="right_link_1" pos="0.0185 -0.3 0.21152">
            <inertial pos="0.008 -0.0023 0.0213" quat="0.707107 0.707107 0 0" mass="0.2154" diaginertia="0.0003 0.0003 0.0002"/>
            <joint name="right_joint_1" pos="0 0 0" axis="0 0 1" range="-2.61 3.14" limited="true" armature="0.1" damping="3.0" frictionloss="1.0"/>
            <geom type="mesh" rgba="0.92549 0.92549 0.92549 1" mesh="arm_link_1"/>

            # right link 2
            <body name="right_link_2" pos="0.02 0 0.045">
                <inertial pos="0.0001 -0.0028 0.1317" quat="0.999789 0.0205404 0 0" mass="1.3123" diaginertia="0.018 0.0177288 0.000671225"/>
                <joint name="right_joint_2" pos="0 0 0" axis="0 1 0" range="-1.57 2.09" limited="true" armature="0.1" damping="3.0" frictionloss="1.0"/>
                <geom type="mesh" rgba="1 1 1 1" mesh="arm_link_2"/>

                # right link 3
                <body name="right_link_3" pos="0 0 0.264">
                    <inertial pos="-0.051 0.0008 0.1447" quat="0.996909 0.0323182 -0.0688403 -0.019747" mass="1.1083" diaginertia="0.0115968 0.0112369 0.00136632"/>
                    <joint name="right_joint_3" pos="0 0 0" axis="0 1 0" range="0 3.14" limited="true" armature="0.1" damping="3.0" frictionloss="1.0"/>
                    <geom type="mesh" rgba="1 1 1 1" mesh="arm_link_3"/>

                    # right link 4
                    <body name="right_link_4" pos="-0.06 0 0.245">
                        <inertial pos="-0.0597 -0.001 0.0572" quat="0 0.92388 0 0.382683" mass="0.5398" diaginertia="0.0011 0.001 0.0005"/>
                        <joint name="right_joint_4" pos="0 0 0" axis="0 1 0" range="-1.57 1.57" limited="true" armature="0.1" damping="3.0" frictionloss="1.0"/>
                        <geom type="mesh" rgba="0.792157 0.792157 0.792157 1" mesh="arm_link_4"/>

                        # right link 5
                        <body name="right_link_5" pos="-0.0553006 0 0.07025">
                            <inertial pos="0.0292 0.0001 -0.0107" quat="0.707107 0 0 0.707107" mass="0.3984" diaginertia="0.0003 0.0002 0.0002"/>
                            <joint name="right_joint_5" pos="0 0 0" axis="-1 0 0" range="-1.57 1.57" limited="true" armature="0.1" damping="3.0" frictionloss="1.0"/>
                            <geom type="mesh" rgba="0.898039 0.917647 0.929412 1" mesh="arm_link_5"/>

                            # right picker base link
                            <body name="right_picker_base_link" pos="0.0547 0 0.02895">
                                <inertial pos="0.00913219 -0.00104428 0.0437714" quat="0.779177 -0.153227 -0.105966 0.598478" mass="0.416893" diaginertia="0.00112999 0.000894143 0.000426247"/>
                                <joint name="right_joint_6" pos="0 0 0" axis="0 0 1" range="-1.57 1.57" limited="true" armature="0.1" damping="3.0" frictionloss="1.0"/>
                                <geom pos="0 0 0.005" type="mesh" mesh="picker_base_link" rgba="0.75 0.75 0.75 1.0" />
                                <camera name="right_camera" pos="-0.07 0.0 0.03" quat="0.1227878 0.6963642 -0.6963642 -0.1227878" fovy="50"/>
                                <geom pos="-0.08 0.0 0.015" quat="0.819152 0.0 -0.5735764 0.0" type="mesh" mesh="camera_link" rgba="0.1 0.1 0.1 1" contype="0" conaffinity="0" />

                                # right narrow gripper
                                <body name="right_picker_narrow1_link" pos="0 -0.0195 0.0565" quat="0.0 -0.707 0.0 -0.707">
                                    <inertial pos="0.0094685 0.0068806 6.5437e-05" quat="0.488058 0.00022793 0.00062709 0.872811" mass="0.025428" diaginertia="2.65562e-06 1.69368e-06 1.5501e-06"/>
                                    <joint name="right_hand_narrow1_joint" pos="0 0 0" axis="0 0 1" range="0.0 0.8" limited="true" armature="0.01" damping="1.0" frictionloss="0.1" />
                                    <geom type="mesh" mesh="picker_narrow1_link" rgba="0.75 0.75 0.75 1.0" />

                                    <body name="right_picker_narrow2_link" pos="0.030852 0.018551 0">
                                        <inertial pos="0.0088027 -0.007035 1.6424e-05" quat="0.259339 0.661207 -0.251356 0.657547" mass="0.0040132" diaginertia="1.70091e-07 1.66561e-07 5.03584e-08"/>
                                        <joint name="right_hand_narrow2_joint" pos="0 0 0" axis="0 0 -1" range="-1.57 1.57" limited="true" armature="0.001" damping="1.0" frictionloss="0.1" springref="-0.01" stiffness="1.0" />
                                        <geom type="mesh" mesh="picker_narrow2_link" rgba="0.75 0.75 0.75 1.0" />

                                        <body name="right_picker_narrow3_link" pos="0.018118 -0.01574 0">
                                            <inertial pos="0.012508 -0.0079729 9.4339e-05" quat="0.575033 0.575033 0.411506 0.411506" mass="0.018029" diaginertia="2.75843e-06 2.3252e-06 9.52273e-07"/>
                                            <joint name="right_hand_narrow3_joint" pos="0 0 0" axis="0 0 -1" range="-0.5 0.5" limited="true" armature="0.001" damping="1.0" frictionloss="0.1" />
                                            <geom type="mesh" mesh="picker_narrow3_link" rgba="0.75 0.75 0.75 1.0" />
                                        </body>
                                    </body>
                                </body>

                                # right narrow helper
                                <body name="right_picker_narrow_loop_link" pos="0 -0.021633 0.07387" quat="0.0 -0.707 0.0 -0.707">
                                    <inertial pos="0.014869 -0.0036066 0.00029307" quat="0.800794 2.10378e-06 -6.78039e-07 0.59894" mass="0.022591" diaginertia="4.76981e-06 4.35879e-06 6.0445e-07"/>
                                    <joint name="right_hand_narrow_loop_joint" pos="0 0 0" axis="0 0 -1" limited="auto" armature="0.0" damping="0.01" frictionloss="0.01" />
                                    <geom type="mesh" mesh="picker_narrow_loop_link" rgba="0.75 0.75 0.75 1.0" />
                                </body>

                                # right wide gripper
                                <body name="right_picker_wide1_link" pos="0 0.0195 0.0565" quat="0.0 -0.707 0.0 -0.707">
                                    <inertial pos="0.0095051 -0.0068479 6.8268e-05" quat="0.872477 -0.000843631 -0.000472499 0.488655" mass="0.025428" diaginertia="2.65502e-06 1.69428e-06 1.5501e-06"/>
                                    <joint name="right_hand_wide1_joint" pos="0 0 0" axis="0 0 -1" range="0.0 0.8" limited="true" armature="0.1" damping="1.0" frictionloss="0.1" />
                                    <geom type="mesh" mesh="picker_wide1_link" rgba="0.75 0.75 0.75 1.0" />

                                    <body name="right_picker_wide2_link" pos="0.030852 -0.018551 0">
                                        <inertial pos="0.0088027 0.007035 -1.6424e-05" quat="-0.251356 0.657548 0.259339 0.661207" mass="0.0040132" diaginertia="1.70091e-07 1.66561e-07 5.03584e-08"/>
                                        <joint name="right_hand_wide2_joint" pos="0 0 0" axis="0 0 -1" range="-1.57 1.57" limited="true" armature="0.001" damping="1.0" frictionloss="0.1" springref="0.01" stiffness="1.0" />
                                        <geom type="mesh" mesh="picker_wide2_link" rgba="0.75 0.75 0.75 1.0" />

                                        <body name="right_picker_wide3_link" pos="0.018118 0.01574 0">
                                            <inertial pos="0.016206 0.0094593 4.7668e-05" quat="0.574355 3.4175e-06 6.47256e-06 0.818606" mass="0.035835" diaginertia="1.16461e-05 8.09447e-06 4.6309e-06"/>
                                            <joint name="right_hand_wide3_joint" pos="0 0 0" axis="0 0 -1" range="-0.5 0.5" limited="true" armature="0.001" damping="1.0" frictionloss="0.1" />
                                            <geom type="mesh" mesh="picker_wide3_link" rgba="0.75 0.75 0.75 1.0" />
                                        </body>
                                    </body>
                                </body>

                                # right wide helper
                                <body name="right_picker_wide_loop_link" pos="0 0.021633 0.07387" quat="0.0 -0.707 0.0 -0.707">
                                    <inertial pos="0.016268 0.0040555 0.00030323" quat="0.599119 -2.137e-06 -5.96717e-07 0.80066" mass="0.025142" diaginertia="6.26903e-06 5.85397e-06 6.2389e-07"/>
                                    <joint name="right_hand_wide_loop_joint" pos="0 0 0" axis="0 0 -1" limited="auto" armature="0.0" damping="0.01" frictionloss="0.01" />
                                    <geom type="mesh" mesh="picker_wide_loop_link" rgba="0.75 0.75 0.75 1.0" />
                                </body>
                            </body>
                        </body>
                    </body>
                </body>
            </body>
        </body>
    </body>
</mujocoinclude>
